>>> raise Exception("Something happened").with_traceback(traceback)
Traceback (most recent call last):
  File "<stdin>", line 1, in <module>
Exception: Something happened
